<?xml version="1.0"?>
<robot xmlns:xacro="http://www.ros.org/wiki/xacro" >

    <material name="white">
        <color rgba="1 1 1 1" />
    </material>

    <material name="orange">
        <color rgba="1 0.3 0.1 1" />
    </material>

    <material name="blue">
        <color rgba="0.2 0.2 1 1" />
    </material>

    <material name="black">
        <color rgba="0 0 0 1" />
    </material>


    <!-- BASE LINK-->
    <link name="base_link">
    </link>


    <!--CHASSIS LINK-->
    <joint name="chassis joint" type="fixed">
        <parent link="base_link"/>
        <child link="chassis"/>
        <origin xyz="0 0 0"/>
    </joint>

    <link name ="chassis">
        <visual>
            <origin xyz="0 0 0"/>
            <geometry>
                <cylinder radius = "0.3" length = "0.05"/>
            </geometry>
            <material name="white"/>
        </visual>
    </link>


    <!--LEFT WHEEL LINK-->
    <joint name="left_wheel joint" type = "continuous">
        <parent link = "base_link"/>
        <child link = "left_wheel"/>
        <origin xyz = "0 0.2 0" rpy = "-${pi/2} 0 0"/>
        <axis xyz = "0 0 1"/>
    </joint>

    <link name = "left_wheel">
        <visual>
            <geometry>
                <cylinder radius = "0.1" length = "0.03"/>
            </geometry>
            <material name = "black"/>
        </visual>
    </link>


    <!--RIGHT WHEEL LINK-->
    <joint name="right_wheel joint" type = "continuous">
        <parent link = "base_link"/>
        <child link = "right_wheel"/>
        <origin xyz = "0 -0.2 0" rpy = "${pi/2} 0 0"/>
        <axis xyz = "0 0 -1"/>
    </joint>

    <link name = "right_wheel">
        <visual>
            <geometry>
                <cylinder radius = "0.1" length = "0.03"/>
            </geometry>
            <material name = "black"/>
        </visual>
    </link>


    <!--CASTER WHEEL1 LINK-->
    <joint name = "caster_wheel1_joint" type = "fixed">
        <parent link = "chassis"/>
        <child link = "caster_wheel1"/>
        <origin xyz = "0.25 0 -0.05"/>
    </joint>

    <link name = "caster_wheel1">
        <visual>
            <geometry>
                <sphere radius = "0.035"/>
            </geometry>
            <material name = "black"/>
        </visual>
    </link>



    <!--CASTER WHEEL2 LINK-->
    <joint name = "caster_wheel2_joint" type = "fixed">
        <parent link = "chassis"/>
        <child link = "caster_wheel2"/>
        <origin xyz = "-0.25 0 -0.05"/>
    </joint>

    <link name = "caster_wheel2">
        <visual>
            <geometry>
                <sphere radius = "0.035"/>
            </geometry>
            <material name = "black"/>
        </visual>
    </link>


</robot>